Workbook

Sheet ธ.ค.  
C1: จักรยานยนต์ ธ.ค. 67 | K1: จักรยานยนต์ ธ.ค. 66 | S1: จักรยานยนต์ ธ.ค. 65 | AA1: จักรยานยนต์ ธ.ค. 64 | AI1: จักรยานยนต์ ธ.ค. 63 | AQ1: จักรยานยนต์ ธ.ค. 62 | AY1: จักรยานยนต์ ธ.ค. 61 | BG1: จักรยานยนต์ ธ.ค. 60 | BP1: จักรยานยนต์ ธ.ค. 59 | BY1: จักรยานยนต์ ธ.ค. 58 | CH1: จักรยานยนต์ ธ.ค. 57 | CQ1: จักรยานยนต์ ธค 56 | CZ1: จักรยานยนต์ ธค 55 | DI1: จักรยานยนต ธค 54 | DR1: จักรยานยนต์ ธค 53 | EA1: จักรยานยนต์ ธค 52 | EJ1: จักรยานยนต์ ธค 51 | ES1: จักรยานยนต์ ธค 50 | FA1: จักรยานยนต์ ธ.ค.49 | FH1: จักรยานยนต์ ธ.ค.48
C2: พ.ย. 68 | D2: ธ.ค. 68 | E2: ร้อยละ | F2: ธ.ค. 67 | G2: ธ.ค. 68 | H2: ร้อยละ | K2: พ.ย. 66 | L2: ธ.ค. 66 | M2: ร้อยละ | N2: ธ.ค. 65 | O2: ธ.ค. 66 | P2: ร้อยละ | S2: พ.ย. 65 | T2: ธ.ค. 65 | U2: ร้อยละ | V2: ธ.ค. 64 | W2: ธ.ค. 65 | X2: ร้อยละ | AA2: พ.ย. 64 | AB2: ธ.ค. 64 | AC2: ร้อยละ | AD2: ธ.ค. 63 | AE2: ธ.ค. 64 | AF2: ร้อยละ | AI2: พ.ย. 63 | AJ2: ธ.ค. 63 | AK2: ร้อยละ | AL2: ธ.ค. 62 | AM2: ธ.ค. 63 | AN2: ร้อยละ | AQ2: พ.ย. 62 | AR2: ธ.ค. 62 | AS2: ร้อยละ | AT2: ธ.ค. 61 | AU2: ธ.ค. 62 | AV2: ร้อยละ | AY2: พ.ย. 61 | AZ2: ธ.ค. 61 | BA2: ร้อยละ | BB2: ธ.ค. 60 | BC2: ธ.ค. 61 | BD2: ร้อยละ | BG2: พ.ย. 60 | BH2: ธ.ค. 60 | BI2: ร้อยละ | BJ2: ธ.ค. 59 | BK2: ธ.ค. 60 | BL2: ร้อยละ | BP2: พ.ย. 59 | BQ2: ธ.ค. 59 | BR2: ร้อยละ | BS2: ธ.ค. 58 | BT2: ธ.ค. 59 | BU2: ร้อยละ | BY2: พย 58 | BZ2: ธค 58 | CA2: ร้อยละ | CB2: ธค 57 | CC2: ธค 58 | CD2: ร้อยละ | CH2: พย 57 | CI2: ธค 57 | CJ2: ร้อยละ | CK2: ธค 56 | CL2: ธค 57 | CM2: ร้อยละ | CQ2: พย 56 | CR2: ธค 56 | CS2: ร้อยละ | CT2: ธค 55 | CU2: ธค 56 | CV2: ร้อยละ | CZ2: พย 55 | DA2: ธค 55 | DB2: ร้อยละ | DC2: ธค 54 | DD2: ธค 55 | DE2: ร้อยละ | DI2: พย 54 | DJ2: ธค 54 | DK2: ร้อยละ | DL2: ธค 53 | DM2: ธค 54 | DN2: ร้อยละ | DR2: พย 53 | DS2: ธค 53 | DT2: ร้อยละ | DU2: ธค 52 | DV2: ธค 53 | DW2: ร้อยละ | EA2: พย 52 | EB2: ธค 52 | EC2: ร้อยละ | ED2: ธค 51 | EE2: ธค 52 | EF2: ร้อยละ | EJ2: พย 51 | EK2: ธค 51 | EL2: ร้อยละ | EM2: ธค 50 | EN2: ธค 51 | EO2: ร้อยละ | ES2: 18568 | ET2: 18598 | EU2: ร้อยละ | EV2: 18233 | EW2: 18598 | EX2: ร้อยละ | FA2: 18203 | FB2: 18233 | FC2: ร้อยละ | FD2: 17868 | FE2: 18233 | FF2: ร้อยละ | FI2: 17838 | FJ2: 17868 | FK2: ร้อยละ | FL2: 17502 | FM2: 17868 | FN2: ร้อยละ
A3: ผลิต | C3: 146167 | D3: 161304 | E3: =((D3-C3)/C3)*100 -> 10.355963 | F3: 153702 | G3: 161304 | H3: =((G3-F3)/F3)*100 -> 4.9459343 | I3: ผลิต | K3: 178045 | L3: 164528 | M3: =((L3-K3)/K3)*100 -> -7.5919009 | N3: 180474 | O3: 164528 | P3: =((O3-N3)/N3)*100 -> -8.8356218 | Q3: ผลิต | S3: 189040 | T3: 180474 | U3: =((T3-S3)/S3)*100 -> -4.5313161 | V3: 167823 | W3: 180474 | X3: =((W3-V3)/V3)*100 -> 7.5382993 | Y3: ผลิต | AA3: 188493 | AB3: 167823 | AC3: =((AB3-AA3)/AA3)*100 -> -10.965924 | AD3: 159099 | AE3: 167823 | AF3: =((AE3-AD3)/AD3)*100 -> 5.4833783 | AG3: ผลิต | AI3: 175569 | AJ3: 159099 | AK3: =((AJ3-AI3)/AI3)*100 -> -9.3809272 | AL3: 158839 | AM3: 159099 | AN3: =((AM3-AL3)/AL3)*100 -> 0.16368776 | AO3: ผลิต | AQ3: 171799 | AR3: 158839 | AS3: =((AR3-AQ3)/AQ3)*100 -> -7.5436993 | AT3: 148791 | AU3: 158839 | AV3: =((AU3-AT3)/AT3)*100 -> 6.7530966 | AW3: ผลิต | AY3: 189690 | AZ3: 148791 | BA3: =((AZ3-AY3)/AY3)*100 -> -21.560968 | BB3: 152315 | BC3: 148791 | BD3: =((BC3-BB3)/BB3)*100 -> -2.3136264 | BE3: ผลิต | BG3: 192451 | BH3: 152315 | BI3: =((BH3-BG3)/BG3)*100 -> -20.855179 | BJ3: 140147 | BK3: 152315 | BL3: =((BK3-BJ3)/BJ3)*100 -> 8.6823121 | BN3: ผลิต | BP3: 163400 | BQ3: 140147 | BR3: =((BQ3-BP3)/BP3)*100 -> -14.230722 | BS3: 144736 | BT3: 140147 | BU3: =((BT3-BS3)/BS3)*100 -> -3.1706003 | BW3: ผลิต | BY3: ='พ.ย. '!CK3 -> #REF! | BZ3: =#REF! -> #REF! | CA3: =((BZ3-BY3)/BY3)*100 -> #REF! | CB3: =#REF! -> #REF! | CC3: =BZ3 -> #REF! | CD3: =((CC3-CB3)/CB3)*100 -> #REF! | CF3: ผลิต | CH3: 149526 | CI3: 153187 | CJ3: =((CI3-CH3)/CH3)*100 -> 2.4484036 | CK3: =SUM(CK4:CK5) -> 143872 | CL3: 153187 | CM3: =((CL3-CK3)/CK3)*100 -> 6.4745051 | CO3: ผลิต | CQ3: 164466 | CR3: 143872 | CS3: =((CR3-CQ3)/CQ3)*100 -> -12.521737 | CT3: 183384 | CU3: 143872 | CV3: =((CU3-CT3)/CT3)*100 -> -21.546045 | CX3: ผลิต | CZ3: =SUM(CZ4:CZ5) -> 196615 | DA3: =SUM(DA4:DA5) -> 183384 | DB3: =((DA3-CZ3)/CZ3)*100 -> -6.729395 | DC3: =SUM(DC4:DC5) -> 151185 | DD3: =SUM(DD4:DD5) -> 183384 | DE3: =((DD3-DC3)/DC3)*100 -> 21.297748 | DG3: ผลิต | DI3: =SUM(DI4:DI5) -> 33424 | DJ3: =SUM(DJ4:DJ5) -> 151185 | DK3: =((DJ3-DI3)/DI3)*100 -> 352.32468 | DL3: 160982 | DM3: =SUM(DM4:DM5) -> 151185 | DN3: =((DM3-DL3)/DL3)*100 -> -6.0857736 | DP3: ผลิต | DR3: =SUM(DR4:DR5) -> 175866 | DS3: =SUM(DS4:DS5) -> 160982 | DT3: =((DS3-DR3)/DR3)*100 -> -8.4632618 | DU3: 141402 | DV3: 160982 | DW3: =((DV3-DU3)/DU3)*100 -> 13.847046 | DY3: ผลิต | EA3: =SUM(EA4:EA5) -> 165557 | EB3: =SUM(EB4:EB5) -> 141402 | EC3: =((EB3-EA3)/EA3)*100 -> -14.590141 | ED3: 136066 | EE3: =SUM(EE4:EE5) -> 141402 | EF3: =((EE3-ED3)/ED3)*100 -> 3.9216263 | EH3: ผลิต | EJ3: =SUM(EJ4:EJ5) -> 173782 | EK3: =SUM(EK4:EK5) -> 136066 | EL3: =((EK3-EJ3)/EJ3)*100 -> -21.703053 | EM3: =SUM(EM4:EM5) -> 133039 | EN3: 136066 | EO3: =((EN3-EM3)/EM3)*100 -> 2.2752727 | EQ3: ผลิต | ES3: =SUM(ES4:ES5) -> 138998 | ET3: =ET4+ET5 -> 133039 | EU3: =(ET3-ES3)/ES3*100 -> -4.287112 | EV3: =SUM(EV4:EV5) -> 152582 | EW3: =EW4+EW5 -> 133039 | EX3: =(EW3-EV3)/EV3*100 -> -12.808195 | EZ3: ผลิต | FA3: 155646 | FB3: 152582 | FC3: =((FB3-FA3)/FA3)*100 -> -1.9685697 | FD3: 192093 | FE3: =FB3 -> 152582 | FF3: =((FE3-FD3)/FD3)*100 -> -20.568683 | FH3: ผลิต | FI3: 225594 | FJ3: 192093 | FK3: =(FJ3-FI3)/FI3*100 -> -14.850129 | FL3: 254396 | FM3: 192093 | FN3: =((FM3-FL3)/FL3)*100 -> -24.490558
B4: ครอบครัว | C4: 119855 | D4: 130481 | E4: =((D4-C4)/C4)*100 -> 8.8657127 | F4: 123007 | G4: 130481 | H4: =((G4-F4)/F4)*100 -> 6.076077 | J4: ครอบครัว | K4: 135391 | L4: 130636 | M4: =((L4-K4)/K4)*100 -> -3.5120503 | N4: 142067 | O4: 130636 | P4: =((O4-N4)/N4)*100 -> -8.0462036 | R4: ครอบครัว | S4: 147360 | T4: 142067 | U4: =((T4-S4)/S4)*100 -> -3.5918838 | V4: 131804 | W4: 142067 | X4: =((W4-V4)/V4)*100 -> 7.7865619 | Z4: ครอบครัว | AA4: 147555 | AB4: 131804 | AC4: =((AB4-AA4)/AA4)*100 -> -10.674664 | AD4: 121636 | AE4: 131804 | AF4: =((AE4-AD4)/AD4)*100 -> 8.3593673 | AH4: ครอบครัว | AI4: 137471 | AJ4: 121636 | AK4: =((AJ4-AI4)/AI4)*100 -> -11.518793 | AL4: 126010 | AM4: 121636 | AN4: =((AM4-AL4)/AL4)*100 -> -3.4711531 | AP4: ครอบครัว | AQ4: 143103 | AR4: 126010 | AS4: =((AR4-AQ4)/AQ4)*100 -> -11.944543 | AT4: 115075 | AU4: 126010 | AV4: =((AU4-AT4)/AT4)*100 -> 9.5024984 | AX4: ครอบครัว | AY4: 148502 | AZ4: 115075 | BA4: =((AZ4-AY4)/AY4)*100 -> -22.509461 | BB4: 113842 | BC4: 115075 | BD4: =((BC4-BB4)/BB4)*100 -> 1.0830801 | BF4: ครอบครัว | BG4: 146474 | BH4: 113842 | BI4: =((BH4-BG4)/BG4)*100 -> -22.278357 | BJ4: 97926 | BK4: 113842 | BL4: =((BK4-BJ4)/BJ4)*100 -> 16.253089 | BO4: ครอบครัว | BP4: 122861 | BQ4: 97926 | BR4: =((BQ4-BP4)/BP4)*100 -> -20.295293 | BS4: 109508 | BT4: 97926 | BU4: =((BT4-BS4)/BS4)*100 -> -10.576396 | BX4: ครอบครัว | BY4: ='พ.ย. '!CK4 -> #REF! | BZ4: =#REF! -> #REF! | CA4: =((BZ4-BY4)/BY4)*100 -> #REF! | CB4: =#REF! -> #REF! | CC4: =BZ4 -> #REF! | CD4: =((CC4-CB4)/CB4)*100 -> #REF! | CG4: ครอบครัว | CH4: 120551 | CI4: 118902 | CJ4: =((CI4-CH4)/CH4)*100 -> -1.3678858 | CK4: 124495 | CL4: 118902 | CM4: =((CL4-CK4)/CK4)*100 -> -4.4925499 | CP4: ครอบครัว | CQ4: 133675 | CR4: 124495 | CS4: =((CR4-CQ4)/CQ4)*100 -> -6.8674023 | CT4: 164370 | CU4: 124495 | CV4: =((CU4-CT4)/CT4)*100 -> -24.259293 | CY4: ครอบครัว | CZ4: 173288 | DA4: 164370 | DB4: =((DA4-CZ4)/CZ4)*100 -> -5.146346 | DC4: 138488 | DD4: 164370 | DE4: =((DD4-DC4)/DC4)*100 -> 18.688984 | DH4: ครอบครัว | DI4: 31492 | DJ4: 138488 | DK4: =((DJ4-DI4)/DI4)*100 -> 339.75613 | DL4: 148407 | DM4: 138488 | DN4: =((DM4-DL4)/DL4)*100 -> -6.683647 | DQ4: ครอบครัว | DR4: =163686+177 -> 163863 | DS4: 148407 | DT4: =((DS4-DR4)/DR4)*100 -> -9.4322696 | DU4: 130952 | DV4: 148407 | DW4: =((DV4-DU4)/DU4)*100 -> 13.329312 | DZ4: ครอบครัว | EA4: 155123 | EB4: 130952 | EC4: =((EB4-EA4)/EA4)*100 -> -15.581829 | ED4: 120295 | EE4: 130952 | EF4: =((EE4-ED4)/ED4)*100 -> 8.8590548 | EI4: ครอบครัว | EJ4: 154637 | EK4: 120295 | EL4: =((EK4-EJ4)/EJ4)*100 -> -22.208139 | EM4: 123958 | EN4: 120295 | EO4: =((EN4-EM4)/EM4)*100 -> -2.9550332 | ER4: ครอบครัว | ES4: 134728 | ET4: 123958 | EU4: =(ET4-ES4)/ES4*100 -> -7.993884 | EV4: 148005 | EW4: 123958 | EX4: =(EW4-EV4)/EV4*100 -> -16.247424 | EZ4: จำหน่าย | FA4: 159737 | FB4: 163197 | FC4: =((FB4-FA4)/FA4)*100 -> 2.1660605 | FD4: 179958 | FE4: 163197 | FF4: =((FE4-FD4)/FD4)*100 -> -9.3138399 | FH4: จำหน่าย | FI4: 197728 | FJ4: 179958 | FK4: =(FJ4-FI4)/FI4*100 -> -8.9870934 | FL4: 188496 | FM4: 179958 | FN4: =((FM4-FL4)/FL4)*100 -> -4.5295391
B5: สปอร์ต | C5: 23324 | D5: 25964 | E5: =((D5-C5)/C5)*100 -> 11.318813 | F5: 25130 | G5: 25964 | H5: =((G5-F5)/F5)*100 -> 3.3187425 | J5: สปอร์ต | K5: 42554 | L5: 33792 | M5: =((L5-K5)/K5)*100 -> -20.590309 | N5: 38407 | O5: 33792 | P5: =((O5-N5)/N5)*100 -> -12.016039 | R5: สปอร์ต | S5: 41680 | T5: 38407 | U5: =((T5-S5)/S5)*100 -> -7.8526871 | V5: 36019 | W5: 38407 | X5: =((W5-V5)/V5)*100 -> 6.6298343 | Z5: สปอร์ต | AA5: 40938 | AB5: 36019 | AC5: =((AB5-AA5)/AA5)*100 -> -12.015731 | AD5: 37463 | AE5: 36019 | AF5: =((AE5-AD5)/AD5)*100 -> -3.8544697 | AH5: สปอร์ต | AI5: 38098 | AJ5: 37463 | AK5: =((AJ5-AI5)/AI5)*100 -> -1.6667542 | AL5: 32829 | AM5: 37463 | AN5: =((AM5-AL5)/AL5)*100 -> 14.115569 | AP5: สปอร์ต | AQ5: 28696 | AR5: 32829 | AS5: =((AR5-AQ5)/AQ5)*100 -> 14.402704 | AT5: 33716 | AU5: 32829 | AV5: =((AU5-AT5)/AT5)*100 -> -2.6307984 | AX5: สปอร์ต | AY5: 41188 | AZ5: 33716 | BA5: =((AZ5-AY5)/AY5)*100 -> -18.141206 | BB5: 38473 | BC5: 33716 | BD5: =((BC5-BB5)/BB5)*100 -> -12.364515 | BF5: สปอร์ต | BG5: 45977 | BH5: 38473 | BI5: =((BH5-BG5)/BG5)*100 -> -16.321204 | BJ5: 42221 | BK5: 38473 | BL5: =((BK5-BJ5)/BJ5)*100 -> -8.8770991 | BO5: สปอร์ต | BP5: 40539 | BQ5: 42221 | BR5: =((BQ5-BP5)/BP5)*100 -> 4.149091 | BS5: 35228 | BT5: 42221 | BU5: =((BT5-BS5)/BS5)*100 -> 19.850687 | BX5: สปอร์ต | BY5: ='พ.ย. '!CK5 -> #REF! | BZ5: =#REF! -> #REF! | CA5: =((BZ5-BY5)/BY5)*100 -> #REF! | CB5: =#REF! -> #REF! | CC5: =BZ5 -> #REF! | CD5: =((CC5-CB5)/CB5)*100 -> #REF! | CG5: สปอร์ต | CH5: 28975 | CI5: 34285 | CJ5: =((CI5-CH5)/CH5)*100 -> 18.326143 | CK5: 19377 | CL5: 34285 | CM5: =((CL5-CK5)/CK5)*100 -> 76.936574 | CP5: สปอร์ต | CQ5: 30791 | CR5: 19377 | CS5: =((CR5-CQ5)/CQ5)*100 -> -37.069273 | CT5: 19014 | CU5: 19377 | CV5: =((CU5-CT5)/CT5)*100 -> 1.9091196 | CY5: สปอร์ต | CZ5: 23327 | DA5: 19014 | DB5: =((DA5-CZ5)/CZ5)*100 -> -18.489304 | DC5: 12697 | DD5: 19014 | DE5: =((DD5-DC5)/DC5)*100 -> 49.75191 | DH5: สปอร์ต | DI5: 1932 | DJ5: 12697 | DK5: =((DJ5-DI5)/DI5)*100 -> 557.19462 | DL5: 12575 | DM5: 12697 | DN5: =((DM5-DL5)/DL5)*100 -> 0.97017893 | DQ5: สปอร์ต | DR5: =11999+4 -> 12003 | DS5: 12575 | DT5: =((DS5-DR5)/DR5)*100 -> 4.7654753 | DU5: 10450 | DV5: 12575 | DW5: =((DV5-DU5)/DU5)*100 -> 20.334928 | DZ5: สปอร์ต | EA5: 10434 | EB5: 10450 | EC5: =((EB5-EA5)/EA5)*100 -> 0.15334483 | ED5: 15771 | EE5: 10450 | EF5: =((EE5-ED5)/ED5)*100 -> -33.739141 | EI5: สปอร์ต | EJ5: 19145 | EK5: 15771 | EL5: =((EK5-EJ5)/EJ5)*100 -> -17.6234 | EM5: 9081 | EN5: 15771 | EO5: =((EN5-EM5)/EM5)*100 -> 73.670301 | ER5: สปอร์ต | ES5: 4270 | ET5: 9081 | EU5: =(ET5-ES5)/ES5*100 -> 112.66979 | EV5: 4577 | EW5: 9081 | EX5: =(EW5-EV5)/EV5*100 -> 98.405069 | EZ5: ส่งออก | FA5: 6149 | FB5: 4734 | FC5: =((FB5-FA5)/FA5)*100 -> -23.011872 | FD5: 11037 | FE5: =FB5 -> 4734 | FF5: =((FE5-FD5)/FD5)*100 -> -57.10791 | FH5: ส่งออก | FI5: 119929 | FJ5: 119173 | FK5: =(FJ5-FI5)/FI5*100 -> -0.63037297 | FL5: 67682 | FM5: 119173 | FN5: =((FM5-FL5)/FL5)*100 -> 76.077835
B6: EV | C6: 1541 | D6: 2248 | E6: =((D6-C6)/C6)*100 -> 45.879299 | F6: 100 | G6: 2248 | H6: =((G6-F6)/F6)*100 -> 2148 | J6: EV | K6: 100 | L6: 100 | M6: =((L6-K6)/K6)*100 -> 0 | O6: 100 | P6: =((O6-N6)/N6)*100 -> #DIV/0!
B7: ICONIC | C7: 1447 | D7: 2611 | E7: =((D7-C7)/C7)*100 -> 80.442294 | F7: 5465 | G7: 2611 | H7: =((G7-F7)/F7)*100 -> -52.223239 | J7: ICONIC | L7: 6201 | M7: =((L7-K7)/K7)*100 -> #DIV/0! | O7: 6201 | P7: =((O7-N7)/N7)*100 -> #DIV/0!
A8: จำหน่าย | C8: 128430 | D8: 134364 | E8: =((D8-C8)/C8)*100 -> 4.6204158 | F8: 124793 | G8: 134364 | H8: =((G8-F8)/F8)*100 -> 7.6695007 | I8: จำหน่าย | K8: 143121 | L8: 132377 | M8: =((L8-K8)/K8)*100 -> -7.5069347 | N8: 144445 | O8: 132377 | P8: =((O8-N8)/N8)*100 -> -8.3547371 | Q8: จำหน่าย | S8: 150980 | T8: 144445 | U8: =((T8-S8)/S8)*100 -> -4.3283879 | V8: 145343 | W8: 144445 | X8: =((W8-V8)/V8)*100 -> -0.61784881 | Y8: จำหน่าย | AA8: 144648 | AB8: 145343 | AC8: =((AB8-AA8)/AA8)*100 -> 0.48047674 | AD8: 123844 | AE8: 145343 | AF8: =((AE8-AD8)/AD8)*100 -> 17.359743 | AG8: จำหน่าย | AI8: 120062 | AJ8: 123844 | AK8: =((AJ8-AI8)/AI8)*100 -> 3.1500391 | AL8: 113615 | AM8: 123844 | AN8: =((AM8-AL8)/AL8)*100 -> 9.0032126 | AO8: จำหน่าย | AQ8: 135458 | AR8: 113615 | AS8: =((AR8-AQ8)/AQ8)*100 -> -16.125293 | AT8: 137300 | AU8: 113615 | AV8: =((AU8-AT8)/AT8)*100 -> -17.250546 | AW8: จำหน่าย | AY8: 145633 | AZ8: 137300 | BA8: =((AZ8-AY8)/AY8)*100 -> -5.7219174 | BB8: 131523 | BC8: 137300 | BD8: =((BC8-BB8)/BB8)*100 -> 4.3923876 | BE8: จำหน่าย | BG8: 153058 | BH8: 131523 | BI8: =((BH8-BG8)/BG8)*100 -> -14.06983 | BJ8: 124667 | BK8: 131523 | BL8: =((BK8-BJ8)/BJ8)*100 -> 5.4994505 | BN8: จำหน่าย | BP8: 137291 | BQ8: 124667 | BR8: =((BQ8-BP8)/BP8)*100 -> -9.1950674 | BS8: 122720 | BT8: 124667 | BU8: =((BT8-BS8)/BS8)*100 -> 1.5865385 | BW8: จำหน่าย | BY8: ='พ.ย. '!CK8 -> #REF! | BZ8: =#REF! -> #REF! | CA8: =((BZ8-BY8)/BY8)*100 -> #REF! | CB8: =#REF! -> #REF! | CC8: =BZ8 -> #REF! | CD8: =((CC8-CB8)/CB8)*100 -> #REF! | CF8: จำหน่าย | CH8: =CH9+CH10+CH11 -> 121025 | CI8: =CI9+CI10+CI11 -> 120001 | CJ8: =((CI8-CH8)/CH8)*100 -> -0.84610618 | CK8: =SUM(CK9:CK11) -> 126752 | CL8: =CL9+CL10+CL11 -> 120001 | CM8: =((CL8-CK8)/CK8)*100 -> -5.3261487 | CO8: จำหน่าย | CQ8: 138750 | CR8: 126852 | CS8: =((CR8-CQ8)/CQ8)*100 -> -8.5751351 | CT8: 152894 | CU8: 126852 | CV8: =((CU8-CT8)/CT8)*100 -> -17.032715 | CX8: จำหน่าย | CZ8: =SUM(CZ9:CZ11) -> 165774 | DA8: =SUM(DA9:DA11) -> 152894 | DB8: =((DA8-CZ8)/CZ8)*100 -> -7.7696141 | DC8: =SUM(DC9:DC11) -> 122377 | DD8: =SUM(DD9:DD11) -> 152894 | DE8: =((DD8-DC8)/DC8)*100 -> 24.936875 | DG8: จำหน่าย | DI8: =SUM(DI9:DI11) -> 128324 | DJ8: =SUM(DJ9:DJ11) -> 122377 | DK8: =((DJ8-DI8)/DI8)*100 -> -4.634363 | DL8: 158006 | DM8: =SUM(DM9:DM11) -> 122377 | DN8: =((DM8-DL8)/DL8)*100 -> -22.549144 | DP8: จำหน่าย | DR8: =SUM(DR9:DR11) -> 144220 | DS8: =SUM(DS9:DS11) -> 158006 | DT8: =((DS8-DR8)/DR8)*100 -> 9.5590071 | DU8: 147424 | DV8: 158006 | DW8: =((DV8-DU8)/DU8)*100 -> 7.1779357 | DY8: จำหน่าย | EA8: =SUM(EA9:EA11) -> 130264 | EB8: =SUM(EB9:EB11) -> 147424 | EC8: =((EB8-EA8)/EA8)*100 -> 13.173248 | ED8: 116026 | EE8: =SUM(EE9:EE11) -> 147424 | EF8: =((EE8-ED8)/ED8)*100 -> 27.061176 | EH8: จำหน่าย | EJ8: =SUM(EJ9:EJ11) -> 125323 | EK8: =SUM(EK9:EK11) -> 116026 | EL8: =((EK8-EJ8)/EJ8)*100 -> -7.4184308 | EM8: =SUM(EM9:EM11) -> 103218 | EN8: 116026 | EO8: =((EN8-EM8)/EM8)*100 -> 12.408688 | EQ8: จำหน่าย | ES8: =SUM(ES9:ES11) -> 129608 | ET8: =SUM(ET9:ET11) -> 103218 | EU8: =(ET8-ES8)/ES8*100 -> -20.361397 | EV8: =SUM(EV9:EV11) -> 163197 | EW8: =SUM(EW9:EW11) -> 103218 | EX8: =(EW8-EV8)/EV8*100 -> -36.752514
B9: - น้อยกว่า 50 ซีซี | C9: 0 | D9: 0 | E9: 0 | F9: 0 | G9: 0 | H9: 0 | J9: - น้อยกว่า 50 ซีซี | K9: 0 | L9: 0 | M9: 0 | N9: 0 | O9: 0 | P9: 0 | R9: - น้อยกว่า 50 ซีซี | S9: 0 | T9: 0 | U9: 0 | V9: 0 | W9: 0 | X9: 0 | Z9: - น้อยกว่า 50 ซีซี | AA9: 0 | AB9: 0 | AC9: 0 | AD9: 0 | AE9: 0 | AF9: 0 | AH9: - น้อยกว่า 50 ซีซี | AI9: 0 | AJ9: 0 | AK9: 0 | AL9: 0 | AM9: 0 | AN9: 0 | AP9: - น้อยกว่า 50 ซีซี | AQ9: 0 | AR9: 0 | AS9: 0 | AT9: 0 | AU9: 0 | AV9: 0 | AX9: - น้อยกว่า 50 ซีซี | AY9: 0 | AZ9: 0 | BA9: 0 | BB9: 0 | BC9: 0 | BD9: 0 | BF9: - น้อยกว่า 50 ซีซี | BG9: 1 | BH9: 0 | BI9: =((BH9-BG9)/BG9)*100 -> -100 | BK9: 0 | BO9: - น้อยกว่าหรือเท่ากับ 100 ซีซี | BP9: 8 | BQ9: 9 | BR9: =((BQ9-BP9)/BP9)*100 -> 12.5 | BT9: 9 | BX9: ครอบครัว | BY9: ='พ.ย. '!CK9 -> #REF! | BZ9: =#REF! -> #REF! | CA9: =((BZ9-BY9)/BY9)*100 -> #REF! | CB9: =#REF! -> #REF! | CC9: =BZ9 -> #REF! | CD9: =((CC9-CB9)/CB9)*100 -> #REF! | CG9: ครอบครัว | CH9: 61747 | CI9: 61058 | CJ9: =((CI9-CH9)/CH9)*100 -> -1.1158437 | CK9: 62927 | CL9: 61058 | CM9: =((CL9-CK9)/CK9)*100 -> -2.9701082 | CP9: ครอบครัว | CQ9: 68128 | CR9: 62927 | CS9: =((CR9-CQ9)/CQ9)*100 -> -7.6341592 | CT9: 71024 | CU9: 62927 | CV9: =((CU9-CT9)/CT9)*100 -> -11.400372 | CY9: ครอบครัว | CZ9: 73163 | DA9: 71024 | DB9: =((DA9-CZ9)/CZ9)*100 -> -2.9236089 | DC9: 50657 | DD9: 71024 | DE9: =((DD9-DC9)/DC9)*100 -> 40.205697 | DH9: ครอบครัว | DI9: 57995 | DJ9: 50657 | DK9: =((DJ9-DI9)/DI9)*100 -> -12.652815 | DL9: 71313 | DM9: 50657 | DN9: =((DM9-DL9)/DL9)*100 -> -28.965266 | DQ9: ครอบครัว | DR9: 66767 | DS9: 71313 | DT9: =((DS9-DR9)/DR9)*100 -> 6.8087528 | DU9: 71790 | DV9: 71313 | DW9: =((DV9-DU9)/DU9)*100 -> -0.66443794 | DZ9: ครอบครัว | EA9: 63240 | EB9: 71790 | EC9: =((EB9-EA9)/EA9)*100 -> 13.519924 | ED9: 56426 | EE9: 71790 | EF9: =((EE9-ED9)/ED9)*100 -> 27.228583 | EI9: ครอบครัว | EJ9: 66671 | EK9: 60171 | EL9: =((EK9-EJ9)/EJ9)*100 -> -9.7493663 | EM9: 53110 | EN9: 60171 | EO9: =((EN9-EM9)/EM9)*100 -> 13.295048 | ER9: ครอบครัว | ES9: 67453 | ET9: 53110 | EU9: =(ET9-ES9)/ES9*100 -> -21.263695 | EV9: 85217 | EW9: 53110 | EX9: =(EW9-EV9)/EV9*100 -> -37.676755 | FA9: รถยนต์ ธ.ค. 49 | FH9: รถยนต์ ธ.ค.48
B10: - 51-110 ซีซี | C10: 40214 | D10: 40786 | E10: =((D10-C10)/C10)*100 -> 1.4223902 | F10: 43663 | G10: 40786 | H10: =((G10-F10)/F10)*100 -> -6.5891029 | J10: - 51-110 ซีซี | K10: 53291 | L10: 51549 | M10: =((L10-K10)/K10)*100 -> -3.2688446 | N10: 64547 | O10: 51549 | P10: =((O10-N10)/N10)*100 -> -20.137264 | R10: - 51-110 ซีซี | S10: 70688 | T10: 64547 | U10: =((T10-S10)/S10)*100 -> -8.6874717 | V10: 71294 | W10: 64547 | X10: =((W10-V10)/V10)*100 -> -9.4636295 | Z10: - 51-110 ซีซี | AA10: 66454 | AB10: 71294 | AC10: =((AB10-AA10)/AA10)*100 -> 7.2832335 | AD10: 59235 | AE10: 71294 | AF10: =((AE10-AD10)/AD10)*100 -> 20.357897 | AH10: - 51-110 ซีซี | AI10: 55990 | AJ10: 59235 | AK10: =((AJ10-AI10)/AI10)*100 -> 5.7956778 | AL10: 56243 | AM10: 59235 | AN10: =((AM10-AL10)/AL10)*100 -> 5.3197731 | AP10: - 51-110 ซีซี | AQ10: 68831 | AR10: 56243 | AS10: =((AR10-AQ10)/AQ10)*100 -> -18.288271 | AT10: 74240 | AU10: 56243 | AV10: =((AU10-AT10)/AT10)*100 -> -24.241649 | AX10: - 51-110 ซีซี | AY10: 77235 | AZ10: 74240 | BA10: =((AZ10-AY10)/AY10)*100 -> -3.8777756 | BB10: 67983 | BC10: 74240 | BD10: =((BC10-BB10)/BB10)*100 -> 9.2037715 | BF10: - 51-110 ซีซี | BG10: 79895 | BH10: 67983 | BI10: =((BH10-BG10)/BG10)*100 -> -14.909569 | BK10: 67983 | BO10: - 101-125 ซีซี | BP10: 117649 | BQ10: 107169 | BR10: =((BQ10-BP10)/BP10)*100 -> -8.907853 | BT10: 107169 | BX10: สกูตเตอร์ | BY10: ='พ.ย. '!CK10 -> #REF! | BZ10: =#REF! -> #REF! | CA10: =((BZ10-BY10)/BY10)*100 -> #REF! | CB10: =#REF! -> #REF! | CC10: =BZ10 -> #REF! | CD10: =((CC10-CB10)/CB10)*100 -> #REF! | CG10: สกูตเตอร์ | CH10: 45455 | CI10: 44351 | CJ10: =((CI10-CH10)/CH10)*100 -> -2.4287757 | CK10: 52384 | CL10: 44351 | CM10: =((CL10-CK10)/CK10)*100 -> -15.334835 | CP10: สกูตเตอร์ | CQ10: 57898 | CR10: 52484 | CS10: =((CR10-CQ10)/CQ10)*100 -> -9.3509275 | CT10: 75702 | CU10: 52484 | CV10: =((CU10-CT10)/CT10)*100 -> -30.67026 | CY10: สกูตเตอร์ | CZ10: 85406 | DA10: 75702 | DB10: =((DA10-CZ10)/CZ10)*100 -> -11.362199 | DC10: 66637 | DD10: 75702 | DE10: =((DD10-DC10)/DC10)*100 -> 13.603554 | DH10: สกูตเตอร์ | DI10: 63063 | DJ10: 66637 | DK10: =((DJ10-DI10)/DI10)*100 -> 5.6673485 | DL10: 82701 | DM10: 66637 | DN10: =((DM10-DL10)/DL10)*100 -> -19.424191 | DQ10: สกูตเตอร์ | DR10: 75078 | DS10: 82701 | DT10: =((DS10-DR10)/DR10)*100 -> 10.15344 | DU10: 69200 | DV10: 82701 | DW10: =((DV10-DU10)/DU10)*100 -> 19.510116 | DZ10: สปอร์ต | EA10: 61341 | EB10: 69200 | EC10: =((EB10-EA10)/EA10)*100 -> 12.811985 | ED10: 54846 | EE10: 69200 | EF10: =((EE10-ED10)/ED10)*100 -> 26.171462 | EI10: สปอร์ต | EJ10: 1486 | EK10: 778 | EL10: =((EK10-EJ10)/EJ10)*100 -> -47.644684 | EM10: 993 | EN10: 778 | EO10: =((EN10-EM10)/EM10)*100 -> -21.651561 | ER10: สปอร์ต | ES10: 1320 | ET10: 993 | EU10: =(ET10-ES10)/ES10*100 -> -24.772727 | EV10: 1924 | EW10: 993 | EX10: =(EW10-EV10)/EV10*100 -> -48.388773 | FA10: 18203 | FB10: 18233 | FC10: ร้อยละ | FD10: 17868 | FE10: 18233 | FF10: ร้อยละ | FI10: 17838 | FJ10: 17868 | FK10: ร้อยละ | FL10: 17502 | FM10: 17868 | FN10: ร้อยละ
B11: - 111-125 ซีซี | C11: 59677 | D11: 62974 | E11: =((D11-C11)/C11)*100 -> 5.5247415 | F11: 50395 | G11: 62974 | H11: =((G11-F11)/F11)*100 -> 24.96081 | J11: - 111-125 ซีซี | K11: 51508 | L11: 46306 | M11: =((L11-K11)/K11)*100 -> -10.099402 | N11: 43621 | O11: 46306 | P11: =((O11-N11)/N11)*100 -> 6.1552922 | R11: - 111-125 ซีซี | S11: 43477 | T11: 43621 | U11: =((T11-S11)/S11)*100 -> 0.33120961 | V11: 38866 | W11: 43621 | X11: =((W11-V11)/V11)*100 -> 12.234344 | Z11: - 111-125 ซีซี | AA11: 41063 | AB11: 38866 | AC11: =((AB11-AA11)/AA11)*100 -> -5.3503154 | AD11: 34450 | AE11: 38866 | AF11: =((AE11-AD11)/AD11)*100 -> 12.818578 | AH11: - 111-125 ซีซี | AI11: 34216 | AJ11: 34450 | AK11: =((AJ11-AI11)/AI11)*100 -> 0.68389058 | AL11: 29234 | AM11: 34450 | AN11: =((AM11-AL11)/AL11)*100 -> 17.842238 | AP11: - 111-125 ซีซี | AQ11: 36123 | AR11: 29234 | AS11: =((AR11-AQ11)/AQ11)*100 -> -19.070952 | AT11: 35097 | AU11: 29234 | AV11: =((AU11-AT11)/AT11)*100 -> -16.705131 | AX11: - 111-125 ซีซี | AY11: 38102 | AZ11: 35097 | BA11: =((AZ11-AY11)/AY11)*100 -> -7.8867251 | BB11: 39714 | BC11: 35097 | BD11: =((BC11-BB11)/BB11)*100 -> -11.625623 | BF11: - 111-125 ซีซี | BG11: 44466 | BH11: 39714 | BI11: =((BH11-BG11)/BG11)*100 -> -10.686817 | BK11: 39714 | BO11: - 126-150 ซีซี | BP11: 13144 | BQ11: 11591 | BR11: =((BQ11-BP11)/BP11)*100 -> -11.815277 | BT11: 11591 | BX11: สปอร์ต | BY11: ='พ.ย. '!CK12 -> #REF! | BZ11: =#REF! -> #REF! | CA11: =((BZ11-BY11)/BY11)*100 -> #REF! | CB11: =#REF! -> #REF! | CC11: =BZ11 -> #REF! | CD11: =((CC11-CB11)/CB11)*100 -> #REF! | CG11: สปอร์ต | CH11: 13823 | CI11: 14592 | CJ11: =((CI11-CH11)/CH11)*100 -> 5.5631918 | CK11: 11441 | CL11: 14592 | CM11: =((CL11-CK11)/CK11)*100 -> 27.541299 | CP11: สปอร์ต | CQ11: 12724 | CR11: 11441 | CS11: =((CR11-CQ11)/CQ11)*100 -> -10.083307 | CT11: 6168 | CU11: 11441 | CV11: =((CU11-CT11)/CT11)*100 -> 85.489624 | CY11: สปอร์ต | CZ11: 7205 | DA11: 6168 | DB11: =((DA11-CZ11)/CZ11)*100 -> -14.392783 | DC11: 5083 | DD11: 6168 | DE11: =((DD11-DC11)/DC11)*100 -> 21.345662 | DH11: สปอร์ต | DI11: 7266 | DJ11: 5083 | DK11: =((DJ11-DI11)/DI11)*100 -> -30.044041 | DL11: 3992 | DM11: 5083 | DN11: =((DM11-DL11)/DL11)*100 -> 27.329659 | DQ11: สปอร์ต | DR11: 2375 | DS11: 3992 | DT11: =((DS11-DR11)/DR11)*100 -> 68.084211 | DU11: 6434 | DV11: 3992 | DW11: =((DV11-DU11)/DU11)*100 -> -37.954616 | DZ11: สกูตเตอร์ | EA11: 5683 | EB11: 6434 | EC11: =((EB11-EA11)/EA11)*100 -> 13.214851 | ED11: 4754 | EE11: 6434 | EF11: =((EE11-ED11)/ED11)*100 -> 35.338662 | EI11: สกูตเตอร์ | EJ11: 57166 | EK11: 55077 | EL11: =((EK11-EJ11)/EJ11)*100 -> -3.65427 | EM11: 49115 | EN11: 55077 | EO11: =((EN11-EM11)/EM11)*100 -> 12.138858 | ER11: สกูตเตอร์ | ES11: 60835 | ET11: 49115 | EU11: =(ET11-ES11)/ES11*100 -> -19.265226 | EV11: 76056 | EW11: 49115 | EX11: =(EW11-EV11)/EV11*100 -> -35.422583 | EZ11: ผลิต | FA11: 101117 | FB11: 91751 | FC11: =((FB11-FA11)/FA11)*100 -> -9.2625375 | FD11: 99019 | FE11: 91751 | FF11: =((FE11-FD11)/FD11)*100 -> -7.3400055 | FH11: ผลิต | FI11: 108176 | FJ11: 99019 | FK11: =(FJ11-FI11)/FI11*100 -> -8.464909 | FL11: 87504 | FM11: 99019 | FN11: =(FM11-FL11)/FL11*100 -> 13.159398
B12: - 126-250 ซีซี | C12: 21942 | D12: 22406 | E12: =((D12-C12)/C12)*100 -> 2.1146659 | F12: 23024 | G12: 22406 | H12: =((G12-F12)/F12)*100 -> -2.6841557 | J12: - 126-250 ซีซี | K12: 29754 | L12: 26376 | M12: =((L12-K12)/K12)*100 -> -11.353095 | N12: 29823 | O12: 26376 | P12: =((O12-N12)/N12)*100 -> -11.558193 | R12: - 126-250 ซีซี | S12: 29652 | T12: 29823 | U12: =((T12-S12)/S12)*100 -> 0.5766896 | V12: 28669 | W12: 29823 | X12: =((W12-V12)/V12)*100 -> 4.0252538 | Z12: - 126-250 ซีซี | AA12: 28920 | AB12: 28669 | AC12: =((AB12-AA12)/AA12)*100 -> -0.86791148 | AD12: 24427 | AE12: 28669 | AF12: =((AE12-AD12)/AD12)*100 -> 17.366029 | AH12: - 126-250 ซีซี | AI12: 24638 | AJ12: 24427 | AK12: =((AJ12-AI12)/AI12)*100 -> -0.85640068 | AL12: 23251 | AM12: 24427 | AN12: =((AM12-AL12)/AL12)*100 -> 5.057847 | AP12: - 126-250 ซีซี | AQ12: 24928 | AR12: 23251 | AS12: =((AR12-AQ12)/AQ12)*100 -> -6.7273748 | AT12: 23337 | AU12: 23251 | AV12: =((AU12-AT12)/AT12)*100 -> -0.36851352 | AX12: - 126-250 ซีซี | AY12: 25136 | AZ12: 23337 | BA12: =((AZ12-AY12)/AY12)*100 -> -7.1570656 | BB12: 19992 | BC12: 23337 | BD12: =((BC12-BB12)/BB12)*100 -> 16.731693 | BF12: - 126-250 ซีซี | BG12: 24240 | BH12: 19992 | BI12: =((BH12-BG12)/BG12)*100 -> -17.524752 | BK12: 19992 | BO12: - มากกว่าหรือเท่ากับ 151 ซีซี | BP12: 6490 | BQ12: 5898 | BR12: =((BQ12-BP12)/BP12)*100 -> -9.1217257 | BT12: 5898
B13: - 251-399 ซีซี | C13: 5794 | D13: 7419 | E13: =((D13-C13)/C13)*100 -> 28.046255 | F13: 6886 | G13: 7419 | H13: =((G13-F13)/F13)*100 -> 7.7403427 | J13: - 251-399 ซีซี | K13: 7499 | L13: 7035 | M13: =((L13-K13)/K13)*100 -> -6.1874917 | N13: 5205 | O13: 7035 | P13: =((O13-N13)/N13)*100 -> 35.158501 | R13: - 251-399 ซีซี | S13: 5809 | T13: 5205 | U13: =((T13-S13)/S13)*100 -> -10.397659 | V13: 5296 | W13: 5205 | X13: =((W13-V13)/V13)*100 -> -1.7182779 | Z13: - 251-399 ซีซี | AA13: 6886 | AB13: 5296 | AC13: =((AB13-AA13)/AA13)*100 -> -23.090328 | AD13: 4250 | AE13: 5296 | AF13: =((AE13-AD13)/AD13)*100 -> 24.611765 | AH13: - 251-399 ซีซี | AI13: 3748 | AJ13: 4250 | AK13: =((AJ13-AI13)/AI13)*100 -> 13.39381 | AL13: 3054 | AM13: 4250 | AN13: =((AM13-AL13)/AL13)*100 -> 39.161755 | AP13: - 251-399 ซีซี | AQ13: 3690 | AR13: 3054 | AS13: =((AR13-AQ13)/AQ13)*100 -> -17.235772 | AT13: 2737 | AU13: 3054 | AV13: =((AU13-AT13)/AT13)*100 -> 11.582024 | AX13: - 251-399 ซีซี | AY13: 2924 | AZ13: 2737 | BA13: =((AZ13-AY13)/AY13)*100 -> -6.3953488 | BB13: 1949 | BC13: 2737 | BD13: =((BC13-BB13)/BB13)*100 -> 40.43099 | BF13: - 251-399 ซีซี | BG13: 2201 | BH13: 1949 | BI13: =((BH13-BG13)/BG13)*100 -> -11.449341 | BK13: 1949
B14: - มากกว่าหรือเท่ากับ 400 ซีซี | C14: 803 | D14: 779 | E14: =((D14-C14)/C14)*100 -> -2.988792 | F14: 825 | G14: 779 | H14: =((G14-F14)/F14)*100 -> -5.5757576 | J14: - มากกว่าหรือเท่ากับ 400 ซีซี | K14: 1069 | L14: 1111 | M14: =((L14-K14)/K14)*100 -> 3.9289055 | N14: 1249 | O14: 1111 | P14: =((O14-N14)/N14)*100 -> -11.048839 | R14: - มากกว่าหรือเท่ากับ 400 ซีซี | S14: 1354 | T14: 1249 | U14: =((T14-S14)/S14)*100 -> -7.7548006 | V14: 1218 | W14: 1249 | X14: =((W14-V14)/V14)*100 -> 2.545156 | Z14: - มากกว่าหรือเท่ากับ 400 ซีซี | AA14: 1325 | AB14: 1218 | AC14: =((AB14-AA14)/AA14)*100 -> -8.0754717 | AD14: 1482 | AE14: 1218 | AF14: =((AE14-AD14)/AD14)*100 -> -17.813765 | AH14: - มากกว่าหรือเท่ากับ 400 ซีซี | AI14: 1470 | AJ14: 1482 | AK14: =((AJ14-AI14)/AI14)*100 -> 0.81632653 | AL14: 1833 | AM14: 1482 | AN14: =((AM14-AL14)/AL14)*100 -> -19.148936 | AP14: - มากกว่าหรือเท่ากับ 400 ซีซี | AQ14: 1886 | AR14: 1833 | AS14: =((AR14-AQ14)/AQ14)*100 -> -2.8101803 | AT14: 1889 | AU14: 1833 | AV14: =((AU14-AT14)/AT14)*100 -> -2.9645315 | AX14: - มากกว่าหรือเท่ากับ 400 ซีซี | AY14: 2236 | AZ14: 1889 | BA14: =((AZ14-AY14)/AY14)*100 -> -15.518784 | BB14: 1885 | BC14: 1889 | BD14: =((BC14-BB14)/BB14)*100 -> 0.21220159 | BF14: - มากกว่าหรือเท่ากับ 400 ซีซี | BG14: 2255 | BH14: 1885 | BI14: =((BH14-BG14)/BG14)*100 -> -16.407982 | BK14: 1885
A15: ส่งออก | B15: (CBU&CKD) | C15: 80554 | D15: 77842 | E15: =((D15-C15)/C15)*100 -> -3.3666857 | F15: 81175 | G15: 77842 | H15: =((G15-F15)/F15)*100 -> -4.1059439 | I15: ส่งออก | J15: (CBU&CKD) | K15: 76148 | L15: 76573 | M15: =((L15-K15)/K15)*100 -> 0.55812365 | N15: 91960 | O15: 76573 | P15: =((O15-N15)/N15)*100 -> -16.732275 | Q15: ส่งออก | R15: (CBU&CKD) | S15: 89707 | T15: 91960 | U15: =((T15-S15)/S15)*100 -> 2.5115097 | V15: 85678 | W15: 91960 | X15: =((W15-V15)/V15)*100 -> 7.3321039 | Y15: ส่งออก | Z15: (CBU&CKD) | AA15: 81029 | AB15: 85678 | AC15: =((AB15-AA15)/AA15)*100 -> 5.737452 | AD15: 78429 | AE15: 85678 | AF15: =((AE15-AD15)/AD15)*100 -> 9.2427546 | AG15: ส่งออก | AH15: (CBU&CKD) | AI15: 67261 | AJ15: 78429 | AK15: =((AJ15-AI15)/AI15)*100 -> 16.603976 | AL15: 97156 | AM15: 78429 | AN15: =((AM15-AL15)/AL15)*100 -> -19.275186 | AO15: ส่งออก | AP15: (CBU&CKD) | AQ15: 94167 | AR15: 97156 | AS15: =((AR15-AQ15)/AQ15)*100 -> 3.1741481 | AT15: 93520 | AU15: 97156 | AV15: =((AU15-AT15)/AT15)*100 -> 3.8879384 | AW15: ส่งออก | AX15: (CBU&CKD) | AY15: 86277 | AZ15: 93520 | BA15: =((AZ15-AY15)/AY15)*100 -> 8.3950531 | BB15: 83382 | BC15: 93520 | BD15: =((BC15-BB15)/BB15)*100 -> 12.158499 | BE15: ส่งออก | BF15: (CBU&CKD) | BG15: 81842 | BH15: 83382 | BI15: =((BH15-BG15)/BG15)*100 -> 1.8816744 | BJ15: 98465 | BK15: 83382 | BL15: =((BK15-BJ15)/BJ15)*100 -> -15.318133 | BN15: ส่งออก | BO15: (CBU&CKD) | BP15: 97248 | BQ15: 98465 | BR15: =((BQ15-BP15)/BP15)*100 -> 1.2514396 | BS15: 92703 | BT15: 98465 | BU15: =((BT15-BS15)/BS15)*100 -> 6.2155486 | BW15: ส่งออก | BX15: (CBU&CKD) | BY15: ='พ.ย. '!CK15 -> #REF! | BZ15: =#REF! -> #REF! | CA15: =((BZ15-BY15)/BY15)*100 -> #REF! | CB15: =#REF! -> #REF! | CC15: =BZ15 -> #REF! | CD15: =((CC15-CB15)/CB15)*100 -> #REF! | CF15: ส่งออก | CG15: (CBU&CKD) | CH15: =CH16+CH17 -> 74348 | CI15: =CI16+CI17 -> 81947 | CJ15: =((CI15-CH15)/CH15)*100 -> 10.220853 | CK15: =SUM(CK16:CK17) -> 89399 | CL15: =CL16+CL17 -> 81947 | CM15: =((CL15-CK15)/CK15)*100 -> -8.3356637 | CO15: ส่งออก | CP15: (CBU&CKD) | CQ15: =SUM(CQ16:CQ17) -> 88054 | CR15: 89399 | CS15: =((CR15-CQ15)/CQ15)*100 -> 1.5274718 | CT15: 85959 | CU15: 89399 | CV15: =((CU15-CT15)/CT15)*100 -> 4.0019079 | CX15: ส่งออก | CY15: (CBU&CKD) | CZ15: =SUM(CZ16:CZ17) -> 81595 | DA15: =SUM(DA16:DA17) -> 85959 | DB15: =((DA15-CZ15)/CZ15)*100 -> 5.3483669 | DC15: =SUM(DC16:DC17) -> 120762 | DD15: =SUM(DD16:DD17) -> 85959 | DE15: =((DD15-DC15)/DC15)*100 -> -28.819496 | DG15: ส่งออก | DH15: (CBU&CKD) | DI15: =SUM(DI16:DI17) -> 37896 | DJ15: =SUM(DJ16:DJ17) -> 120762 | DK15: =((DJ15-DI15)/DI15)*100 -> 218.66688 | DL15: 91580 | DM15: =SUM(DM16:DM17) -> 120762 | DN15: =((DM15-DL15)/DL15)*100 -> 31.865036 | DP15: ส่งออก | DQ15: (CBU&CKD) | DR15: =SUM(DR16:DR17) -> 93967 | DS15: =SUM(DS16:DS17) -> 91580 | DT15: =((DS15-DR15)/DR15)*100 -> -2.5402535 | DU15: 63971 | DV15: 91580 | DW15: =((DV15-DU15)/DU15)*100 -> 43.158619 | DY15: ส่งออก | DZ15: (CBU&CKD) | EA15: =SUM(EA16:EA17) -> 72299 | EB15: =SUM(EB16:EB17) -> 63971 | EC15: =((EB15-EA15)/EA15)*100 -> -11.518832 | ED15: 72961 | EE15: =SUM(EE16:EE17) -> 63971 | EF15: =((EE15-ED15)/ED15)*100 -> -12.321651 | EH15: ส่งออก | EI15: (CBU&CKD) | EJ15: =SUM(EJ16:EJ17) -> 70581 | EK15: =SUM(EK16:EK17) -> 72961 | EL15: =((EK15-EJ15)/EJ15)*100 -> 3.3720123 | EM15: =SUM(EM16:EM17) -> 172027 | EN15: 72961 | EO15: =((EN15-EM15)/EM15)*100 -> -57.587472 | EQ15: ส่งออก | ER15: (CBU&CKD) | ES15: =ES16+ES17 -> 144852 | ET15: =ET16+ET17 -> 172027 | EU15: =(ET15-ES15)/ES15*100 -> 18.760528 | EV15: =SUM(EV16:EV17) -> 150654 | EW15: =EW16+EW17 -> 172027 | EX15: =(EW15-EV15)/EV15*100 -> 14.186812 | EZ15: จำหน่าย | FA15: 57800 | FB15: 84521 | FC15: =((FB15-FA15)/FA15)*100 -> 46.230104 | FD15: 77856 | FE15: 84521 | FF15: =((FE15-FD15)/FD15)*100 -> 8.5606761 | FH15: จำหน่าย | FI15: 63417 | FJ15: 77856 | FK15: =(FJ15-FI15)/FI15*100 -> 22.768343 | FL15: 73251 | FM15: 77856 | FN15: =(FM15-FL15)/FL15*100 -> 6.2866036
B16: CBU | C16: 27081 | D16: 30674 | E16: =((D16-C16)/C16)*100 -> 13.267605 | F16: 32263 | G16: 30674 | H16: =((G16-F16)/F16)*100 -> -4.9251465 | J16: CBU | K16: 43347 | L16: 39973 | M16: =((L16-K16)/K16)*100 -> -7.783699 | N16: 52060 | O16: 39973 | P16: =((O16-N16)/N16)*100 -> -23.217441 | R16: CBU | S16: 40697 | T16: 52060 | U16: =((T16-S16)/S16)*100 -> 27.920977 | V16: 36078 | W16: 52060 | X16: =((W16-V16)/V16)*100 -> 44.298464 | Z16: CBU | AA16: 37890 | AB16: 36078 | AC16: =((AB16-AA16)/AA16)*100 -> -4.7822644 | AD16: 33059 | AE16: 36078 | AF16: =((AE16-AD16)/AD16)*100 -> 9.1321577 | AH16: CBU | AI16: 28819 | AJ16: 33059 | AK16: =((AJ16-AI16)/AI16)*100 -> 14.712516 | AL16: 37280 | AM16: 33059 | AN16: =((AM16-AL16)/AL16)*100 -> -11.322425 | AP16: CBU | AQ16: 31277 | AR16: 37280 | AS16: =((AR16-AQ16)/AQ16)*100 -> 19.193017 | AT16: 38324 | AU16: 37280 | AV16: =((AU16-AT16)/AT16)*100 -> -2.7241415 | AX16: CBU | AY16: 32174 | AZ16: 38324 | BA16: =((AZ16-AY16)/AY16)*100 -> 19.114813 | BB16: 35582 | BC16: 38324 | BD16: =((BC16-BB16)/BB16)*100 -> 7.7061436 | BF16: CBU | BG16: 33822 | BH16: 35582 | BI16: =((BH16-BG16)/BG16)*100 -> 5.2037136 | BJ16: 34466 | BK16: 35582 | BL16: =((BK16-BJ16)/BJ16)*100 -> 3.2379737 | BO16: CBU | BP16: 29934 | BQ16: 34466 | BR16: =((BQ16-BP16)/BP16)*100 -> 15.139975 | BS16: 32683 | BT16: 34466 | BU16: =((BT16-BS16)/BS16)*100 -> 5.4554355 | BX16: CBU | BY16: ='พ.ย. '!CK16 -> #REF! | BZ16: =#REF! -> #REF! | CA16: =((BZ16-BY16)/BY16)*100 -> #REF! | CB16: =#REF! -> #REF! | CC16: =BZ16 -> #REF! | CD16: =((CC16-CB16)/CB16)*100 -> #REF! | CG16: CBU | CH16: 22872 | CI16: 29597 | CJ16: =((CI16-CH16)/CH16)*100 -> 29.402763 | CK16: 28300 | CL16: 29597 | CM16: =((CL16-CK16)/CK16)*100 -> 4.5830389 | CP16: CBU | CQ16: 29331 | CR16: 28300 | CS16: =((CR16-CQ16)/CQ16)*100 -> -3.5150523 | CT16: 26449 | CU16: 28300 | CV16: =((CU16-CT16)/CT16)*100 -> 6.9983742 | CY16: CBU | CZ16: 24053 | DA16: 26449 | DB16: =((DA16-CZ16)/CZ16)*100 -> 9.9613354 | DC16: 16178 | DD16: 26449 | DE16: =((DD16-DC16)/DC16)*100 -> 63.487452 | DH16: CBU | DI16: 1978 | DJ16: 16178 | DK16: =((DJ16-DI16)/DI16)*100 -> 717.89687 | DL16: 17125 | DM16: 16178 | DN16: =((DM16-DL16)/DL16)*100 -> -5.529927 | DQ16: CBU | DR16: 15407 | DS16: 17125 | DT16: =((DS16-DR16)/DR16)*100 -> 11.150776 | DU16: 8420 | DV16: 17125 | DW16: =((DV16-DU16)/DU16)*100 -> 103.3848 | DZ16: CBU | EA16: 8081 | EB16: 8420 | EC16: =((EB16-EA16)/EA16)*100 -> 4.1950254 | ED16: 17512 | EE16: 8420 | EF16: =((EE16-ED16)/ED16)*100 -> -51.918684 | EI16: CBU | EJ16: 16348 | EK16: 17512 | EL16: =((EK16-EJ16)/EJ16)*100 -> 7.120137 | EM16: 9747 | EN16: 17512 | EO16: =((EN16-EM16)/EM16)*100 -> 79.665538 | ER16: CBU | ES16: 7072 | ET16: 9747 | EU16: =(ET16-ES16)/ES16*100 -> 37.825226 | EV16: 4734 | EW16: 9747 | EX16: =(EW16-EV16)/EV16*100 -> 105.89354 | EZ16: ส่งออก | FA16: 44085 | FB16: 54896 | FC16: =((FB16-FA16)/FA16)*100 -> 24.52308 | FD16: 38303 | FE16: =FB16 -> 54896 | FF16: =((FE16-FD16)/FD16)*100 -> 43.320367 | FH16: ส่งออก | FI16: 40952 | FJ16: 38303 | FK16: =(FJ16-FI16)/FI16*100 -> -6.4685485 | FL16: 34383 | FM16: 38303 | FN16: =(FM16-FL16)/FL16*100 -> 11.400983
B17: CKD | C17: 53473 | D17: 47168 | E17: =((D17-C17)/C17)*100 -> -11.790997 | F17: 48912 | G17: 47168 | H17: =((G17-F17)/F17)*100 -> -3.5655872 | J17: CKD | K17: 32801 | L17: 36600 | M17: =((L17-K17)/K17)*100 -> 11.581964 | N17: 39900 | O17: 36600 | P17: =((O17-N17)/N17)*100 -> -8.2706767 | R17: CKD | S17: 49010 | T17: 39900 | U17: =((T17-S17)/S17)*100 -> -18.588043 | V17: 49600 | W17: 39900 | X17: =((W17-V17)/V17)*100 -> -19.556452 | Z17: CKD | AA17: 43139 | AB17: 49600 | AC17: =((AB17-AA17)/AA17)*100 -> 14.977167 | AD17: 45370 | AE17: 49600 | AF17: =((AE17-AD17)/AD17)*100 -> 9.3233414 | AH17: CKD | AI17: 38442 | AJ17: 45370 | AK17: =((AJ17-AI17)/AI17)*100 -> 18.021955 | AL17: 59876 | AM17: 45370 | AN17: =((AM17-AL17)/AL17)*100 -> -24.226735 | AP17: CKD | AQ17: 62890 | AR17: 59876 | AS17: =((AR17-AQ17)/AQ17)*100 -> -4.7924948 | AT17: 55196 | AU17: 59876 | AV17: =((AU17-AT17)/AT17)*100 -> 8.4788753 | AX17: CKD | AY17: 54103 | AZ17: 55196 | BA17: =((AZ17-AY17)/AY17)*100 -> 2.0202207 | BB17: 47800 | BC17: 55196 | BD17: =((BC17-BB17)/BB17)*100 -> 15.472803 | BF17: CKD | BG17: 48020 | BH17: 47800 | BI17: =((BH17-BG17)/BG17)*100 -> -0.45814244 | BJ17: 63999 | BK17: 47800 | BL17: =((BK17-BJ17)/BJ17)*100 -> -25.311333 | BO17: CKD | BP17: 67314 | BQ17: 63999 | BR17: =((BQ17-BP17)/BP17)*100 -> -4.9246813 | BS17: 60020 | BT17: 63999 | BU17: =((BT17-BS17)/BS17)*100 -> 6.6294568 | BX17: CKD | BY17: ='พ.ย. '!CK17 -> #REF! | BZ17: =#REF! -> #REF! | CA17: =((BZ17-BY17)/BY17)*100 -> #REF! | CB17: =#REF! -> #REF! | CC17: =BZ17 -> #REF! | CD17: =((CC17-CB17)/CB17)*100 -> #REF! | CG17: CKD | CH17: 51476 | CI17: 52350 | CJ17: =((CI17-CH17)/CH17)*100 -> 1.6978786 | CK17: 61099 | CL17: 52350 | CM17: =((CL17-CK17)/CK17)*100 -> -14.319383 | CP17: CKD | CQ17: 58723 | CR17: 61099 | CS17: =((CR17-CQ17)/CQ17)*100 -> 4.0461148 | CT17: 59510 | CU17: 61099 | CV17: =((CU17-CT17)/CT17)*100 -> 2.6701395 | CY17: CKD | CZ17: 57542 | DA17: 59510 | DB17: =((DA17-CZ17)/CZ17)*100 -> 3.4201105 | DC17: 104584 | DD17: 59510 | DE17: =((DD17-DC17)/DC17)*100 -> -43.098371 | DH17: CKD | DI17: 35918 | DJ17: 104584 | DK17: =((DJ17-DI17)/DI17)*100 -> 191.17434 | DL17: 74455 | DM17: 104584 | DN17: =((DM17-DL17)/DL17)*100 -> 40.466053 | DQ17: CKD | DR17: 78560 | DS17: 74455 | DT17: =((DS17-DR17)/DR17)*100 -> -5.2253055 | DU17: 55551 | DV17: 74455 | DW17: =((DV17-DU17)/DU17)*100 -> 34.02999 | DZ17: CKD | EA17: 64218 | EB17: 55551 | EC17: =((EB17-EA17)/EA17)*100 -> -13.496216 | ED17: 55449 | EE17: 55551 | EF17: =((EE17-ED17)/ED17)*100 -> 0.18395282 | EI17: CKD | EJ17: 54233 | EK17: 55449 | EL17: =((EK17-EJ17)/EJ17)*100 -> 2.2421773 | EM17: 162280 | EN17: 55449 | EO17: =((EN17-EM17)/EM17)*100 -> -65.831279 | ER17: CKD | ES17: 137780 | ET17: 162280 | EU17: =(ET17-ES17)/ES17*100 -> 17.781971 | EV17: 145920 | EW17: 162280 | EX17: =(EW17-EV17)/EV17*100 -> 11.211623
B18: ล้านบาท | C18: 5160.9006 | D18: 5192.1195 | E18: =((D18-C18)/C18)*100 -> 0.60491194 | F18: 5361.5808 | G18: 5192.1195 | H18: =((G18-F18)/F18)*100 -> -3.1606595 | J18: ล้านบาท | K18: 6849.0454 | L18: 5764.1399 | M18: =((L18-K18)/K18)*100 -> -15.840244 | N18: 7113.9868 | O18: 5764.1399 | P18: =((O18-N18)/N18)*100 -> -18.974548 | R18: ล้านบาท | S18: 6595.988 | T18: 7113.9868 | U18: =((T18-S18)/S18)*100 -> 7.8532396 | V18: 5629.15 | W18: 7113.9868 | X18: =((W18-V18)/V18)*100 -> 26.377637 | Z18: ล้านบาท | AA18: 5798.69 | AB18: 5629.15 | AC18: =((AB18-AA18)/AA18)*100 -> -2.9237638 | AD18: 32756.807 | AE18: 5629.15 | AF18: =((AE18-AD18)/AD18)*100 -> -82.815327 | AH18: ล้านบาท | AI18: 5968.19 | AJ18: 32756.807 | AK18: =((AJ18-AI18)/AI18)*100 -> 448.85663 | AL18: 7121.84 | AM18: 32756.807 | AN18: =((AM18-AL18)/AL18)*100 -> 359.94865 | AP18: ล้านบาท | AQ18: 6939.76 | AR18: 7121.84 | AS18: =((AR18-AQ18)/AQ18)*100 -> 2.6237219 | AT18: 6673.09 | AU18: 7121.84 | AV18: =((AU18-AT18)/AT18)*100 -> 6.7247707 | AX18: ล้านบาท | AY18: 5886.98 | AZ18: 6673.09 | BA18: =((AZ18-AY18)/AY18)*100 -> 13.353366 | BB18: 5329.61 | BC18: 6673.09 | BD18: =((BC18-BB18)/BB18)*100 -> 25.207848 | BF18: ล้านบาท | BG18: 5346.67 | BH18: 5329.61 | BI18: =((BH18-BG18)/BG18)*100 -> -0.31907711 | BJ18: 4777.31 | BK18: 5329.61 | BL18: =((BK18-BJ18)/BJ18)*100 -> 11.560899 | BO18: ล้านบาท | BP18: 4330.19 | BQ18: 4777.31 | BR18: =((BQ18-BP18)/BP18)*100 -> 10.325644 | BS18: 4596.39 | BT18: 4777.31 | BU18: =((BT18-BS18)/BS18)*100 -> 3.9361325 | BX18: ล้านบาท | BY18: ='พ.ย. '!CK18 -> #REF! | BZ18: =#REF! -> #REF! | CA18: =((BZ18-BY18)/BY18)*100 -> #REF! | CB18: =#REF! -> #REF! | CC18: =BZ18 -> #REF! | CD18: =((CC18-CB18)/CB18)*100 -> #REF! | CG18: ล้านบาท | CH18: 3581.27 | CI18: 4400.15 | CJ18: =((CI18-CH18)/CH18)*100 -> 22.865631 | CK18: 4839.41 | CL18: 4400.15 | CM18: =((CL18-CK18)/CK18)*100 -> -9.0767263 | CP18: ล้านบาท | CQ18: 4758.21 | CR18: 4839.41 | CS18: =((CR18-CQ18)/CQ18)*100 -> 1.7065241 | CT18: 2912.95 | CU18: 4839.41 | CV18: =((CU18-CT18)/CT18)*100 -> 66.134331 | CY18: ล้านบาท | CZ18: 2594.46 | DA18: 2912.95 | DB18: =((DA18-CZ18)/CZ18)*100 -> 12.275772 | DC18: 1614.05 | DD18: 2912.95 | DE18: =((DD18-DC18)/DC18)*100 -> 80.474583 | DH18: ล้านบาท | DI18: 336.21 | DJ18: 1614.05 | DK18: =((DJ18-DI18)/DI18)*100 -> 380.07198 | DL18: 2611.31 | DM18: 1614.05 | DN18: =((DM18-DL18)/DL18)*100 -> -38.190027 | DQ18: ล้านบาท | DR18: 2554.63 | DS18: 2611.31 | DT18: =((DS18-DR18)/DR18)*100 -> 2.2187166 | DU18: 1847.88 | DV18: 2611.31 | DW18: =((DV18-DU18)/DU18)*100 -> 41.31383 | DZ18: ล้านบาท | EA18: 1817.36 | EB18: 1847.88 | EC18: =((EB18-EA18)/EA18)*100 -> 1.6793591 | ED18: 2877.11 | EE18: 1847.88 | EF18: =((EE18-ED18)/ED18)*100 -> -35.77305 | EI18: ล้านบาท | EJ18: 2763.42 | EK18: 2877.11 | EL18: =((EK18-EJ18)/EJ18)*100 -> 4.114105 | EM18: 2291.58 | EN18: 2877.11 | EO18: =((EN18-EM18)/EM18)*100 -> 25.551366 | ER18: ล้านบาท | ES18: 2452.01 | ET18: 2291.58 | EU18: =(ET18-ES18)/ES18*100 -> -6.5427955 | EV18: 1984.62 | EW18: 2291.58 | EX18: =(EW18-EV18)/EV18*100 -> 15.466941
C20: รถยนต์ ธ.ค. 68 | K20: รถยนต์ ธ.ค. 66 | S20: รถยนต์ ธ.ค. 65 | AA20: รถยนต์ ธ.ค. 64 | AI20: รถยนต์ ธ.ค. 63 | AQ20: รถยนต์ ธ.ค. 62 | AY20: รถยนต์ ธ.ค. 61 | BG20: รถยนต์ ธ.ค. 60 | BP20: รถยนต์ ธ.ค. 59 | BY20: รถยนต์ ธ.ค. 58 | CH20: รถยนต์ ธ.ค. 57 | CQ20: รถยนต์ ธค 56 | CZ20: รถยนต์ ธค 55 | DI20: รถยนต์ ธค 54 | DR20: รถยนต์ ธค 53 | EA20: รถยนต์ ธค 52 | EJ20: รถยนต์ ธค 51 | ES20: รถยนต์ ธค 50
C21: พ.ย. 68 | D21: ธ.ค. 68 | E21: ร้อยละ | F21: ธ.ค. 67 | G21: ธ.ค. 68 | H21: ร้อยละ | K21: พ.ย. 66 | L21: ธ.ค. 66 | M21: ร้อยละ | N21: ธ.ค. 65 | O21: ธ.ค. 66 | P21: ร้อยละ | S21: พ.ย. 65 | T21: ธ.ค. 65 | U21: ร้อยละ | V21: ธ.ค. 64 | W21: ธ.ค. 65 | X21: ร้อยละ | AA21: พ.ย. 64 | AB21: ธ.ค. 64 | AC21: ร้อยละ | AD21: ธ.ค. 63 | AE21: ธ.ค. 64 | AF21: ร้อยละ | AI21: พ.ย. 63 | AJ21: ธ.ค. 63 | AK21: ร้อยละ | AL21: ธ.ค. 62 | AM21: ธ.ค. 63 | AN21: ร้อยละ | AQ21: 22951 | AR21: 22981 | AS21: ร้อยละ | AT21: 22616 | AU21: 22981 | AV21: ร้อยละ | AY21: พ.ย. 61 | AZ21: ธ.ค. 61 | BA21: ร้อยละ | BB21: ธ.ค. 60 | BC21: ธ.ค. 61 | BD21: ร้อยละ | BG21: พ.ย. 60 | BH21: ธ.ค. 60 | BI21: ร้อยละ | BJ21: ธ.ค. 59 | BK21: ธ.ค. 60 | BL21: ร้อยละ | BP21: พ.ย. 59 | BQ21: ธ.ค. 59 | BR21: ร้อยละ | BS21: ธ.ค. 58 | BT21: ธ.ค. 59 | BU21: ร้อยละ | BY21: =BY2 -> พย 58 | BZ21: =BZ2 -> ธค 58 | CA21: =CA2 -> ร้อยละ | CB21: =CB2 -> ธค 57 | CC21: =CC2 -> ธค 58 | CD21: =CD2 -> ร้อยละ | CH21: พย 57 | CI21: ธค 57 | CJ21: ร้อยละ | CK21: ธค 56 | CL21: ธค 57 | CM21: ร้อยละ | CQ21: พย 56 | CR21: ธค 56 | CS21: ร้อยละ | CT21: ธค 55 | CU21: ธค 56 | CV21: ร้อยละ | CZ21: พย 55 | DA21: ธค 55 | DB21: ร้อยละ | DC21: ธค 54 | DD21: ธค 55 | DE21: ร้อยละ | DI21: พย 54 | DJ21: ธค 54 | DK21: ร้อยละ | DL21: พย 53 | DM21: ธค 54 | DN21: ร้อยละ | DR21: พย 53 | DS21: ธค 53 | DT21: ร้อยละ | DU21: ธค 52 | DV21: ธค 53 | DW21: ร้อยละ | EA21: พย 52 | EB21: ธค 52 | EC21: ร้อยละ | ED21: ธค 51 | EE21: ธค 52 | EF21: ร้อยละ | EJ21: 18933 | EK21: 18963 | EL21: ร้อยละ | EM21: ธค 50 | EN21: ธค 51 | EO21: ร้อยละ | ES21: 18568 | ET21: 18598 | EU21: ร้อยละ | EV21: 18233 | EW21: 18598 | EX21: ร้อยละ
A22: ผลิต | C22: 130222 | D22: 113855 | E22: =((D22-C22)/C22)*100 -> -12.568537 | F22: 104878 | G22: 113855 | H22: =((G22-F22)/F22)*100 -> 8.5594691 | I22: ผลิต | K22: 163337 | L22: 133621 | M22: =((L22-K22)/K22)*100 -> -18.193061 | N22: 158606 | O22: 133621 | P22: =((O22-N22)/N22)*100 -> -15.752872 | Q22: ผลิต | S22: 190155 | T22: 158606 | U22: =((T22-S22)/S22)*100 -> -16.591202 | V22: 154368 | W22: 158606 | X22: =((W22-V22)/V22)*100 -> 2.7453876 | Y22: ผลิต | AA22: 165353 | AB22: 154368 | AC22: =((AB22-AA22)/AA22)*100 -> -6.643363 | AD22: 143073 | AE22: 154368 | AF22: =((AE22-AD22)/AD22)*100 -> 7.8945713 | AG22: ผลิต | AI22: 172455 | AJ22: 143073 | AK22: =((AJ22-AI22)/AI22)*100 -> -17.037488 | AL22: 134208 | AM22: 143073 | AN22: =((AM22-AL22)/AL22)*100 -> 6.6054185 | AO22: ผลิต | AQ22: 154088 | AR22: 134208 | AS22: =((AR22-AQ22)/AQ22)*100 -> -12.901718 | AT22: 169355 | AU22: 134208 | AV22: =((AU22-AT22)/AT22)*100 -> -20.753447 | AW22: ผลิต | AY22: 197020 | AZ22: 169355 | BA22: =((AZ22-AY22)/AY22)*100 -> -14.041722 | BB22: 157207 | BC22: 169355 | BD22: =((BC22-BB22)/BB22)*100 -> 7.7273913 | BE22: ผลิต | BG22: 190385 | BH22: 157207 | BI22: =((BH22-BG22)/BG22)*100 -> -17.426793 | BJ22: 135792 | BK22: 157207 | BL22: =((BK22-BJ22)/BJ22)*100 -> 15.770443 | BN22: ผลิต | BP22: 170784 | BQ22: 135792 | BR22: =((BQ22-BP22)/BP22)*100 -> -20.489039 | BS22: 152692 | BT22: 135792 | BU22: =((BT22-BS22)/BS22)*100 -> -11.068032 | BW22: ผลิต | BY22: ='พ.ย. '!CK22 -> #REF! | BZ22: =CC22 -> #REF! | CA22: =((BZ22-BY22)/BY22)*100 -> #REF! | CB22: =CI22 -> 153669 | CC22: =#REF! -> #REF! | CD22: =((CC22-CB22)/CB22)*100 -> #REF! | CF22: ผลิต | CH22: 158038 | CI22: 153669 | CJ22: =((CI22-CH22)/CH22)*100 -> -2.764525 | CK22: =SUM(CK23:CK25) -> 158893 | CL22: 153669 | CM22: =((CL22-CK22)/CK22)*100 -> -3.2877471 | CO22: ผลิต | CQ22: 182818 | CR22: 158893 | CS22: =((CR22-CQ22)/CQ22)*100 -> -13.086786 | CT22: 221353 | CU22: 158893 | CV22: =((CU22-CT22)/CT22)*100 -> -28.217372 | CX22: ผลิต | CZ22: =SUM(CZ23:CZ25) -> 256581 | DA22: =SUM(DA23:DA25) -> 221353 | DB22: =((DA22-CZ22)/CZ22)*100 -> -13.729777 | DC22: =SUM(DC23:DC25) -> 99426 | DD22: =SUM(DD23:DD25) -> 221353 | DE22: =((DD22-DC22)/DC22)*100 -> 122.6309 | DG22: ผลิต | DI22: =SUM(DI23:DI25) -> 23695 | DJ22: =SUM(DJ23:DJ25) -> 99426 | DK22: =((DJ22-DI22)/DI22)*100 -> 319.60751 | DL22: 137403 | DM22: =SUM(DM23:DM25) -> 96426 | DN22: =((DM22-DL22)/DL22)*100 -> -29.822493 | DP22: ผลิต | DR22: =SUM(DR23:DR25) -> 157982 | DS22: =SUM(DS23:DS25) -> 137403 | DT22: =((DS22-DR22)/DR22)*100 -> -13.026168 | DU22: 111722 | DV22: =SUM(DV23:DV25) -> 137403 | DW22: =((DV22-DU22)/DU22)*100 -> 22.98652 | DY22: ผลิต | EA22: =SUM(EA23:EA25) -> 120985 | EB22: =SUM(EB23:EB25) -> 111722 | EC22: =((EB22-EA22)/EA22)*100 -> -7.656321 | ED22: 84602 | EE22: 111722 | EF22: =((EE22-ED22)/ED22)*100 -> 32.05598 | EH22: ผลิต | EJ22: =SUM(EJ23:EJ25) -> 116041 | EK22: 84602 | EL22: =((EK22-EJ22)/EJ22)*100 -> -27.09301 | EM22: =SUM(EM23:EM25) -> 105024 | EN22: =SUM(EN23:EN25) -> 84602 | EO22: =((EN22-EM22)/EM22)*100 -> -19.445079 | EQ22: ผลิต | ES22: =SUM(ES23:ES25) -> 125071 | ET22: =SUM(ET23:ET25) -> 105024 | EU22: =(ET22-ES22)/ES22*100 -> -16.028496 | EV22: =SUM(EV23:EV25) -> 91751 | EW22: =SUM(EW23:EW25) -> 105024 | EX22: =(EW22-EV22)/EV22*100 -> 14.466327
B23: รถยนต์นั่ง | C23: 52006 | D23: 45087 | E23: =((D23-C23)/C23)*100 -> -13.304234 | F23: 37893 | G23: 45087 | H23: =((G23-F23)/F23)*100 -> 18.985037 | J23: รถยนต์นั่ง | K23: 59532 | L23: 49422 | M23: =((L23-K23)/K23)*100 -> -16.982463 | N23: 53731 | O23: 49422 | P23: =((O23-N23)/N23)*100 -> -8.019579 | R23: รถยนต์นั่ง | S23: 69060 | T23: 53731 | U23: =((T23-S23)/S23)*100 -> -22.196641 | V23: 49868 | W23: 53731 | X23: =((W23-V23)/V23)*100 -> 7.7464506 | Z23: รถยนต์นั่ง | AA23: 55572 | AB23: 49868 | AC23: =((AB23-AA23)/AA23)*100 -> -10.264162 | AD23: 53737 | AE23: 49868 | AF23: =((AE23-AD23)/AD23)*100 -> -7.1998809 | AH23: รถยนต์นั่ง | AI23: 65740 | AJ23: 53737 | AK23: =((AJ23-AI23)/AI23)*100 -> -18.25829 | AL23: 51379 | AM23: 53737 | AN23: =((AM23-AL23)/AL23)*100 -> 4.5894237 | AP23: รถยนต์นั่ง | AQ23: 60077 | AR23: 51379 | AS23: =((AR23-AQ23)/AQ23)*100 -> -14.478086 | AT23: 66484 | AU23: 51379 | AV23: =((AU23-AT23)/AT23)*100 -> -22.719752 | AX23: รถยนต์นั่ง | AY23: 77899 | AZ23: 66484 | BA23: =((AZ23-AY23)/AY23)*100 -> -14.65359 | BB23: 64307 | BC23: 66484 | BD23: =((BC23-BB23)/BB23)*100 -> 3.3853235 | BF23: รถยนต์นั่ง | BG23: 78928 | BH23: 64307 | BI23: =((BH23-BG23)/BG23)*100 -> -18.524478 | BJ23: 55918 | BK23: 64307 | BL23: =((BK23-BJ23)/BJ23)*100 -> 15.002325 | BO23: รถยนต์นั่ง | BP23: 68731 | BQ23: 55918 | BR23: =((BQ23-BP23)/BP23)*100 -> -18.642243 | BS23: 56735 | BT23: 55918 | BU23: =((BT23-BS23)/BS23)*100 -> -1.4400282 | BX23: รถยนต์นั่ง | BY23: ='พ.ย. '!CK23 -> #REF! | BZ23: =CC23 -> #REF! | CA23: =((BZ23-BY23)/BY23)*100 -> #REF! | CB23: =CI23 -> 63533 | CC23: =#REF! -> #REF! | CD23: =((CC23-CB23)/CB23)*100 -> #REF! | CG23: รถยนต์นั่ง | CH23: 64869 | CI23: 63533 | CJ23: =((CI23-CH23)/CH23)*100 -> -2.0595354 | CK23: 64717 | CL23: 63533 | CM23: =((CL23-CK23)/CK23)*100 -> -1.8295038 | CP23: รถยนต์นั่ง | CQ23: 75669 | CR23: 64717 | CS23: =((CR23-CQ23)/CQ23)*100 -> -14.473562 | CT23: 97713 | CU23: 64717 | CV23: =((CU23-CT23)/CT23)*100 -> -33.768281 | CY23: รถยนต์นั่ง | CZ23: 112423 | DA23: 97713 | DB23: =((DA23-CZ23)/CZ23)*100 -> -13.084511 | DC23: 34036 | DD23: 97713 | DE23: =((DD23-DC23)/DC23)*100 -> 187.0872 | DH23: รถยนต์นั่ง | DI23: 10094 | DJ23: 34036 | DK23: =((DJ23-DI23)/DI23)*100 -> 237.19041 | DL23: 50580 | DM23: 31036 | DN23: =((DM23-DL23)/DL23)*100 -> -38.639779 | DQ23: รถยนต์นั่ง | DR23: 57536 | DS23: 50580 | DT23: =((DS23-DR23)/DR23)*100 -> -12.089822 | DU23: 33635 | DV23: 50580 | DW23: =((DV23-DU23)/DU23)*100 -> 50.379069 | DZ23: รถยนต์นั่ง | EA23: 36534 | EB23: 33635 | EC23: =((EB23-EA23)/EA23)*100 -> -7.9350742 | ED23: 24693 | EE23: 33635 | EF23: =((EE23-ED23)/ED23)*100 -> 36.212692 | EI23: รถยนต์นั่ง | EJ23: 33975 | EK23: 24693 | EL23: =((EK23-EJ23)/EJ23)*100 -> -27.320088 | EM23: 24861 | EN23: 24693 | EO23: =((EN23-EM23)/EM23)*100 -> -0.67575721 | ER23: รถยนต์นั่ง | ES23: 28618 | ET23: 24861 | EU23: =(ET23-ES23)/ES23*100 -> -13.128101 | EV23: 22626 | EW23: 24861 | EX23: =(EW23-EV23)/EV23*100 -> 9.8780164
B24: กระบะ 1 ตัน | C24: 76022 | D24: 66475 | E24: =((D24-C24)/C24)*100 -> -12.558207 | F24: 65168 | G24: 66475 | H24: =((G24-F24)/F24)*100 -> 2.0055856 | J24: กระบะ 1 ตัน | K24: 99234 | L24: 80489 | M24: =((L24-K24)/K24)*100 -> -18.889695 | N24: 102362 | O24: 80489 | P24: =((O24-N24)/N24)*100 -> -21.368281 | R24: กระบะ 1 ตัน | S24: 116794 | T24: 102362 | U24: =((T24-S24)/S24)*100 -> -12.356799 | V24: 100662 | W24: 102362 | X24: =((W24-V24)/V24)*100 -> 1.68882 | Z24: กระบะ 1 ตัน | AA24: 105197 | AB24: 100662 | AC24: =((AB24-AA24)/AA24)*100 -> -4.3109594 | AD24: 86423 | AE24: 100662 | AF24: =((AE24-AD24)/AD24)*100 -> 16.475938 | AH24: กระบะ 1 ตัน | AI24: 103153 | AJ24: 86423 | AK24: =((AJ24-AI24)/AI24)*100 -> -16.218627 | AL24: 80032 | AM24: 86423 | AN24: =((AM24-AL24)/AL24)*100 -> 7.9855558 | AP24: กระบะ 1 ตัน | AQ24: 90761 | AR24: 80032 | AS24: =((AR24-AQ24)/AQ24)*100 -> -11.821157 | AT24: 99295 | AU24: 80032 | AV24: =((AU24-AT24)/AT24)*100 -> -19.399768 | AX24: กระบะ 1 ตัน | AY24: 115545 | AZ24: 99295 | BA24: =((AZ24-AY24)/AY24)*100 -> -14.063785 | BB24: 89828 | BC24: 99295 | BD24: =((BC24-BB24)/BB24)*100 -> 10.53903 | BF24: กระบะ 1 ตัน | BG24: 107608 | BH24: 89828 | BI24: =((BH24-BG24)/BG24)*100 -> -16.522935 | BJ24: 76619 | BK24: 89828 | BL24: =((BK24-BJ24)/BJ24)*100 -> 17.239849 | BO24: กระบะ 1 ตัน | BP24: 98274 | BQ24: 76619 | BR24: =((BQ24-BP24)/BP24)*100 -> -22.03533 | BS24: 93444 | BT24: 76619 | BU24: =((BT24-BS24)/BS24)*100 -> -18.005436 | BX24: กระบะ 1 ตัน | BY24: ='พ.ย. '!CK24 -> #REF! | BZ24: =CC24 -> #REF! | CA24: =((BZ24-BY24)/BY24)*100 -> #REF! | CB24: =CI24 -> 87343 | CC24: =#REF! -> #REF! | CD24: =((CC24-CB24)/CB24)*100 -> #REF! | CG24: กระบะ 1 ตัน | CH24: 90221 | CI24: 87343 | CJ24: =((CI24-CH24)/CH24)*100 -> -3.1899447 | CK24: =8533+34408+48796 -> 91737 | CL24: 87343 | CM24: =((CL24-CK24)/CK24)*100 -> -4.7897795 | CP24: กระบะ 1 ตัน | CQ24: 103847 | CR24: 91737 | CS24: =((CR24-CQ24)/CQ24)*100 -> -11.661386 | CT24: 119319 | CU24: 91737 | CV24: =((CU24-CT24)/CT24)*100 -> -23.116184 | CY24: กระบะ 1 ตัน | CZ24: 139536 | DA24: 119319 | DB24: =((DA24-CZ24)/CZ24)*100 -> -14.488734 | DC24: 63170 | DD24: 119319 | DE24: =((DD24-DC24)/DC24)*100 -> 88.885547 | DH24: กระบะ 1 ตัน | DI24: 12574 | DJ24: 63170 | DK24: =((DJ24-DI24)/DI24)*100 -> 402.38588 | DL24: 84535 | DM24: 63170 | DN24: =((DM24-DL24)/DL24)*100 -> -25.273555 | DQ24: กระบะ 1 ตัน | DR24: 97608 | DS24: 84535 | DT24: =((DS24-DR24)/DR24)*100 -> -13.393369 | DU24: 76473 | DV24: 84535 | DW24: =((DV24-DU24)/DU24)*100 -> 10.542283 | DZ24: กระบะ 1 ตัน | EA24: 82741 | EB24: 76473 | EC24: =((EB24-EA24)/EA24)*100 -> -7.5754463 | ED24: 58841 | EE24: 76473 | EF24: =((EE24-ED24)/ED24)*100 -> 29.9655 | EI24: กระบะ 1 ตัน | EJ24: 80750 | EK24: 58841 | EL24: =((EK24-EJ24)/EJ24)*100 -> -27.131889 | EM24: 78268 | EN24: 58841 | EO24: =((EN24-EM24)/EM24)*100 -> -24.821127 | ER24: กระบะ 1 ตัน | ES24: 94309 | ET24: 78268 | EU24: =(ET24-ES24)/ES24*100 -> -17.008981 | EV24: 67555 | EW24: 78268 | EX24: =(EW24-EV24)/EV24*100 -> 15.85819
B25: รถยนต์พาณิชย์ | C25: =C22-C23-C24 -> 2194 | D25: 2293 | E25: =((D25-C25)/C25)*100 -> 4.5123063 | F25: 1817 | G25: 2293 | H25: =((G25-F25)/F25)*100 -> 26.197028 | J25: รถยนต์พาณิชย์ | K25: 4571 | L25: 3710 | M25: =((L25-K25)/K25)*100 -> -18.836141 | N25: 2513 | O25: 3710 | P25: =((O25-N25)/N25)*100 -> 47.632312 | R25: รถยนต์พาณิชย์ | S25: 4301 | T25: 2513 | U25: =((T25-S25)/S25)*100 -> -41.571728 | V25: 3838 | W25: 2513 | X25: =((W25-V25)/V25)*100 -> -34.523189 | Z25: รถยนต์พาณิชย์ | AA25: 4584 | AB25: 3838 | AC25: =((AB25-AA25)/AA25)*100 -> -16.273997 | AD25: 2913 | AE25: 3838 | AF25: =((AE25-AD25)/AD25)*100 -> 31.754205 | AH25: รถยนต์พาณิชย์ | AI25: 3562 | AJ25: 2913 | AK25: =((AJ25-AI25)/AI25)*100 -> -18.220101 | AL25: 2797 | AM25: 2913 | AN25: =((AM25-AL25)/AL25)*100 -> 4.1473007 | AP25: รถยนต์พาณิชย์ | AQ25: 3250 | AR25: 2797 | AS25: =((AR25-AQ25)/AQ25)*100 -> -13.938462 | AT25: 3576 | AU25: 2797 | AV25: =((AU25-AT25)/AT25)*100 -> -21.784116 | AX25: รถยนต์พาณิชย์ | AY25: 3576 | AZ25: 3576 | BA25: =((AZ25-AY25)/AY25)*100 -> 0 | BB25: 3072 | BC25: 3576 | BD25: =((BC25-BB25)/BB25)*100 -> 16.40625 | BF25: รถยนต์พาณิชย์ | BG25: 3849 | BH25: 3072 | BI25: =((BH25-BG25)/BG25)*100 -> -20.187062 | BJ25: 3255 | BK25: 3072 | BL25: =((BK25-BJ25)/BJ25)*100 -> -5.6221198 | BO25: รถยนต์พาณิชย์ | BP25: 3779 | BQ25: 3255 | BR25: =((BQ25-BP25)/BP25)*100 -> -13.866102 | BS25: 2513 | BT25: 3255 | BU25: =((BT25-BS25)/BS25)*100 -> 29.526462 | BX25: รถยนต์พาณิชย์ | BY25: ='พ.ย. '!CK25 -> #REF! | BZ25: =CC25 -> #REF! | CA25: =((BZ25-BY25)/BY25)*100 -> #REF! | CB25: =CI25 -> 2793 | CC25: =#REF! -> #REF! | CD25: =((CC25-CB25)/CB25)*100 -> #REF! | CG25: รถยนต์พาณิชย์ | CH25: 2948 | CI25: 2793 | CJ25: =((CI25-CH25)/CH25)*100 -> -5.2578019 | CK25: =54+437+122+1826 -> 2439 | CL25: 2793 | CM25: =((CL25-CK25)/CK25)*100 -> 14.514145 | CP25: รถยนต์พาณิชย์ | CQ25: 3302 | CR25: 2439 | CS25: =((CR25-CQ25)/CQ25)*100 -> -26.135675 | CT25: 4321 | CU25: 2439 | CV25: =((CU25-CT25)/CT25)*100 -> -43.554733 | CY25: รถยนต์พาณิชย์ | CZ25: 4622 | DA25: 4321 | DB25: =((DA25-CZ25)/CZ25)*100 -> -6.5123323 | DC25: 2220 | DD25: 4321 | DE25: =((DD25-DC25)/DC25)*100 -> 94.63964 | DH25: รถยนต์พาณิชย์ | DI25: 1027 | DJ25: 2220 | DK25: =((DJ25-DI25)/DI25)*100 -> 116.16358 | DL25: 2288 | DM25: 2220 | DN25: =((DM25-DL25)/DL25)*100 -> -2.972028 | DQ25: รถยนต์พาณิชย์ | DR25: 2838 | DS25: 2288 | DT25: =((DS25-DR25)/DR25)*100 -> -19.379845 | DU25: 1614 | DV25: 2288 | DW25: =((DV25-DU25)/DU25)*100 -> 41.759603 | DZ25: รถยนต์พาณิชย์ | EA25: 1710 | EB25: 1614 | EC25: =((EB25-EA25)/EA25)*100 -> -5.6140351 | ED25: 1068 | EE25: 1614 | EF25: =((EE25-ED25)/ED25)*100 -> 51.123596 | EI25: รถยนต์พาณิชย์ | EJ25: 1316 | EK25: 1068 | EL25: =((EK25-EJ25)/EJ25)*100 -> -18.844985 | EM25: 1895 | EN25: 1068 | EO25: =((EN25-EM25)/EM25)*100 -> -43.641161 | ER25: รถยนต์พาณิชย์ | ES25: 2144 | ET25: 1895 | EU25: =(ET25-ES25)/ES25*100 -> -11.613806 | EV25: 1570 | EW25: 1895 | EX25: =(EW25-EV25)/EV25*100 -> 20.700637
A26: จำหน่าย | C26: 51044 | D26: 75121 | E26: =((D26-C26)/C26)*100 -> 47.169109 | F26: 54016 | G26: 75121 | H26: =((G26-F26)/F26)*100 -> 39.071757 | I26: จำหน่าย | K26: 61621 | L26: 68326 | M26: =((L26-K26)/K26)*100 -> 10.881031 | N26: =82799 -> 82799 | O26: 68326 | P26: =((O26-N26)/N26)*100 -> -17.47968 | Q26: จำหน่าย | S26: 68284 | T26: 82799 | U26: =((T26-S26)/S26)*100 -> 21.25681 | V26: =86145+2044+2223+306+287 -> 91005 | W26: =82799 -> 82799 | X26: =((W26-V26)/V26)*100 -> -9.017087 | Y26: จำหน่าย | AA26: 71716 | AB26: 86145 | AC26: =((AB26-AA26)/AA26)*100 -> 20.119639 | AD26: 104089 | AE26: 86145 | AF26: =((AE26-AD26)/AD26)*100 -> -17.239093 | AG26: จำหน่าย | AI26: 79177 | AJ26: 104089 | AK26: =((AJ26-AI26)/AI26)*100 -> 31.463683 | AL26: 89285 | AM26: 104089 | AN26: =((AM26-AL26)/AL26)*100 -> 16.580613 | AO26: จำหน่าย | AQ26: 79299 | AR26: 89285 | AS26: =((AR26-AQ26)/AQ26)*100 -> 12.592845 | AT26: 113581 | AU26: 89285 | AV26: =((AU26-AT26)/AT26)*100 -> -21.390902 | AW26: จำหน่าย | AY26: 94643 | AZ26: 113581 | BA26: =((AZ26-AY26)/AY26)*100 -> 20.009932 | BB26: 104302 | BC26: 113581 | BD26: =((BC26-BB26)/BB26)*100 -> 8.896282 | BE26: จำหน่าย | BG26: 78082 | BH26: 104302 | BI26: =((BH26-BG26)/BG26)*100 -> 33.580082 | BJ26: 86858 | BK26: 104302 | BL26: =((BK26-BJ26)/BJ26)*100 -> 20.083354 | BN26: จำหน่าย | BP26: 64771 | BQ26: 86858 | BR26: =((BQ26-BP26)/BP26)*100 -> 34.100137 | BS26: 101464 | BT26: 86858 | BU26: =((BT26-BS26)/BS26)*100 -> -14.395253 | BW26: จำหน่าย | BY26: ='พ.ย. '!CK26 -> #REF! | BZ26: =#REF! -> #REF! | CA26: =((BZ26-BY26)/BY26)*100 -> #REF! | CB26: =CI26 -> 89504 | CC26: =#REF! -> #REF! | CD26: =((CC26-CB26)/CB26)*100 -> #REF! | CF26: จำหน่าย | CH26: =CH27+CH28+CH29+CH30 -> 73068 | CI26: =CI27+CI28+CI29+CI30 -> 89504 | CJ26: =((CI26-CH26)/CH26)*100 -> 22.494115 | CK26: 113921 | CL26: =CL27+CL28+CL29+CL30 -> 89504 | CM26: =((CL26-CK26)/CK26)*100 -> -21.433274 | CO26: จำหน่าย | CQ26: 93483 | CR26: 113921 | CS26: =((CR26-CQ26)/CQ26)*100 -> 21.862799 | CT26: 144676 | CU26: 113921 | CV26: =((CU26-CT26)/CT26)*100 -> -21.257845 | CX26: จำหน่าย | CZ26: =SUM(CZ27:CZ30) -> 148243 | DA26: =SUM(DA27:DA30) -> 144676 | DB26: =((DA26-CZ26)/CZ26)*100 -> -2.4061844 | DC26: =SUM(DC27:DC30) -> 54575 | DD26: =SUM(DD27:DD30) -> 144676 | DE26: =((DD26-DC26)/DC26)*100 -> 165.09574 | DG26: จำหน่าย | DI26: =SUM(DI27:DI30) -> 25664 | DJ26: =SUM(DJ27:DJ30) -> 54575 | DK26: =((DJ26-DI26)/DI26)*100 -> 112.65196 | DL26: 93122 | DM26: =SUM(DM27:DM30) -> 54575 | DN26: =((DM26-DL26)/DL26)*100 -> -41.394085 | DP26: จำหน่าย | DR26: 78874 | DS26: =SUM(DS27:DS30) -> 93122 | DT26: =((DS26-DR26)/DR26)*100 -> 18.064254 | DU26: 72085 | DV26: =SUM(DV27:DV30) -> 93122 | DW26: =((DV26-DU26)/DU26)*100 -> 29.183603 | DY26: จำหน่าย | EA26: =SUM(EA27:EA30) -> 57031 | EB26: =SUM(EB27:EB30) -> 72085 | EC26: =((EB26-EA26)/EA26)*100 -> 26.396171 | ED26: 59002 | EE26: 72085 | EF26: =((EE26-ED26)/ED26)*100 -> 22.173825 | EH26: จำหน่าย | EJ26: =SUM(EJ27:EJ30) -> 46068 | EK26: 59002 | EL26: =((EK26-EJ26)/EJ26)*100 -> 28.075888 | EM26: =SUM(EM27:EM30) -> 64346 | EN26: =SUM(EN27:EN30) -> 59002 | EO26: =((EN26-EM26)/EM26)*100 -> -8.3051006 | EQ26: จำหน่าย | ES26: =SUM(ES27:ES30) -> 57719 | ET26: =SUM(ET27:ET30) -> 64346 | EU26: =(ET26-ES26)/ES26*100 -> 11.481488 | EV26: =SUM(EV27:EV30) -> 84521 | EW26: =SUM(EW27:EW30) -> 64346 | EX26: =(EW26-EV26)/EV26*100 -> -23.869808
